
Randaugment!
Number of final features: 64
Number of model parameters: 1730519
Traceback (most recent call last):
  File "/home/yu-jw19/venom/project2/train.py", line 578, in <module>
    main()
  File "/home/yu-jw19/venom/project2/train.py", line 405, in main
    train_metrics = train(train_loader, model, ce_criterion, optimizer, epoch)
  File "/home/yu-jw19/venom/project2/train.py", line 439, in train
    for i, (x, target) in enumerate(train_loader):
  File "/home/yu-jw19/.local/lib/python3.9/site-packages/torch/utils/data/dataloader.py", line 521, in __next__
    data = self._next_data()
  File "/home/yu-jw19/.local/lib/python3.9/site-packages/torch/utils/data/dataloader.py", line 1203, in _next_data
    return self._process_data(data)
  File "/home/yu-jw19/.local/lib/python3.9/site-packages/torch/utils/data/dataloader.py", line 1229, in _process_data
    data.reraise()
  File "/home/yu-jw19/.local/lib/python3.9/site-packages/torch/_utils.py", line 425, in reraise
    raise self.exc_type(msg)
TypeError: Caught TypeError in DataLoader worker process 0.
Original Traceback (most recent call last):
  File "/home/yu-jw19/.local/lib/python3.9/site-packages/PIL/Image.py", line 2772, in fromarray
    mode, rawmode = _fromarray_typemap[typekey]
KeyError: ((1, 1), '<i8')
The above exception was the direct cause of the following exception:
Traceback (most recent call last):
  File "/home/yu-jw19/.local/lib/python3.9/site-packages/torch/utils/data/_utils/worker.py", line 287, in _worker_loop
    data = fetcher.fetch(index)
  File "/home/yu-jw19/.local/lib/python3.9/site-packages/torch/utils/data/_utils/fetch.py", line 44, in fetch
    data = [self.dataset[idx] for idx in possibly_batched_index]
  File "/home/yu-jw19/.local/lib/python3.9/site-packages/torch/utils/data/_utils/fetch.py", line 44, in <listcomp>
    data = [self.dataset[idx] for idx in possibly_batched_index]
  File "/home/yu-jw19/venom/project2/dataset.py", line 33, in __getitem__
    img = Image.fromarray(img)
  File "/home/yu-jw19/.local/lib/python3.9/site-packages/PIL/Image.py", line 2774, in fromarray
    raise TypeError("Cannot handle this data type: %s, %s" % typekey) from e
TypeError: Cannot handle this data type: (1, 1), <i8
Traceback (most recent call last):
  File "/home/yu-jw19/venom/project2/train.py", line 578, in <module>
    main()
  File "/home/yu-jw19/venom/project2/train.py", line 405, in main
    train_metrics = train(train_loader, model, ce_criterion, optimizer, epoch)
  File "/home/yu-jw19/venom/project2/train.py", line 439, in train
    for i, (x, target) in enumerate(train_loader):
  File "/home/yu-jw19/.local/lib/python3.9/site-packages/torch/utils/data/dataloader.py", line 521, in __next__
    data = self._next_data()
  File "/home/yu-jw19/.local/lib/python3.9/site-packages/torch/utils/data/dataloader.py", line 1203, in _next_data
    return self._process_data(data)
  File "/home/yu-jw19/.local/lib/python3.9/site-packages/torch/utils/data/dataloader.py", line 1229, in _process_data
    data.reraise()
  File "/home/yu-jw19/.local/lib/python3.9/site-packages/torch/_utils.py", line 425, in reraise
    raise self.exc_type(msg)
TypeError: Caught TypeError in DataLoader worker process 0.
Original Traceback (most recent call last):
  File "/home/yu-jw19/.local/lib/python3.9/site-packages/PIL/Image.py", line 2772, in fromarray
    mode, rawmode = _fromarray_typemap[typekey]
KeyError: ((1, 1), '<i8')
The above exception was the direct cause of the following exception:
Traceback (most recent call last):
  File "/home/yu-jw19/.local/lib/python3.9/site-packages/torch/utils/data/_utils/worker.py", line 287, in _worker_loop
    data = fetcher.fetch(index)
  File "/home/yu-jw19/.local/lib/python3.9/site-packages/torch/utils/data/_utils/fetch.py", line 44, in fetch
    data = [self.dataset[idx] for idx in possibly_batched_index]
  File "/home/yu-jw19/.local/lib/python3.9/site-packages/torch/utils/data/_utils/fetch.py", line 44, in <listcomp>
    data = [self.dataset[idx] for idx in possibly_batched_index]
  File "/home/yu-jw19/venom/project2/dataset.py", line 33, in __getitem__
    img = Image.fromarray(img)
  File "/home/yu-jw19/.local/lib/python3.9/site-packages/PIL/Image.py", line 2774, in fromarray
    raise TypeError("Cannot handle this data type: %s, %s" % typekey) from e
TypeError: Cannot handle this data type: (1, 1), <i8