
Randaugment!
Number of final features: 64
Number of model parameters: 466423
Traceback (most recent call last):
  File "/home/yu-jw19/venom/project2/train.py", line 579, in <module>
    main()
  File "/home/yu-jw19/venom/project2/train.py", line 406, in main
    train_metrics = train(train_loader, model, ce_criterion, optimizer, epoch)
  File "/home/yu-jw19/venom/project2/train.py", line 440, in train
    for i, (x, target) in enumerate(train_loader):
  File "/home/yu-jw19/.local/lib/python3.9/site-packages/torch/utils/data/dataloader.py", line 521, in __next__
    data = self._next_data()
  File "/home/yu-jw19/.local/lib/python3.9/site-packages/torch/utils/data/dataloader.py", line 1203, in _next_data
    return self._process_data(data)
  File "/home/yu-jw19/.local/lib/python3.9/site-packages/torch/utils/data/dataloader.py", line 1229, in _process_data
    data.reraise()
  File "/home/yu-jw19/.local/lib/python3.9/site-packages/torch/_utils.py", line 425, in reraise
    raise self.exc_type(msg)
ValueError: Caught ValueError in DataLoader worker process 0.
Original Traceback (most recent call last):
  File "/home/yu-jw19/.local/lib/python3.9/site-packages/torch/utils/data/_utils/worker.py", line 287, in _worker_loop
    data = fetcher.fetch(index)
  File "/home/yu-jw19/.local/lib/python3.9/site-packages/torch/utils/data/_utils/fetch.py", line 44, in fetch
    data = [self.dataset[idx] for idx in possibly_batched_index]
  File "/home/yu-jw19/.local/lib/python3.9/site-packages/torch/utils/data/_utils/fetch.py", line 44, in <listcomp>
    data = [self.dataset[idx] for idx in possibly_batched_index]
  File "/home/yu-jw19/venom/project2/dataset.py", line 46, in __getitem__
    im = self.transform(im)
  File "/home/yu-jw19/.local/lib/python3.9/site-packages/torchvision/transforms/transforms.py", line 60, in __call__
    img = t(img)
  File "/home/yu-jw19/venom/project2/aug_lib.py", line 723, in __call__
    img = op.pil_transformer(1., self.m)(img)
  File "/home/yu-jw19/venom/project2/aug_lib.py", line 92, in __call__
    return self.f(pil_img)
  File "/home/yu-jw19/venom/project2/aug_lib.py", line 108, in return_function
    im = self.xform(im, level)
  File "/home/yu-jw19/venom/project2/aug_lib.py", line 326, in _brightness_impl
    return ImageEnhance.Brightness(img).enhance(1+v)
  File "/home/yu-jw19/.local/lib/python3.9/site-packages/PIL/ImageEnhance.py", line 36, in enhance
    return Image.blend(self.degenerate, self.image, factor)
  File "/home/yu-jw19/.local/lib/python3.9/site-packages/PIL/Image.py", line 3011, in blend
    return im1._new(core.blend(im1.im, im2.im, alpha))
ValueError: image has wrong mode
Traceback (most recent call last):
  File "/home/yu-jw19/venom/project2/train.py", line 579, in <module>
    main()
  File "/home/yu-jw19/venom/project2/train.py", line 406, in main
    train_metrics = train(train_loader, model, ce_criterion, optimizer, epoch)
  File "/home/yu-jw19/venom/project2/train.py", line 440, in train
    for i, (x, target) in enumerate(train_loader):
  File "/home/yu-jw19/.local/lib/python3.9/site-packages/torch/utils/data/dataloader.py", line 521, in __next__
    data = self._next_data()
  File "/home/yu-jw19/.local/lib/python3.9/site-packages/torch/utils/data/dataloader.py", line 1203, in _next_data
    return self._process_data(data)
  File "/home/yu-jw19/.local/lib/python3.9/site-packages/torch/utils/data/dataloader.py", line 1229, in _process_data
    data.reraise()
  File "/home/yu-jw19/.local/lib/python3.9/site-packages/torch/_utils.py", line 425, in reraise
    raise self.exc_type(msg)
ValueError: Caught ValueError in DataLoader worker process 0.
Original Traceback (most recent call last):
  File "/home/yu-jw19/.local/lib/python3.9/site-packages/torch/utils/data/_utils/worker.py", line 287, in _worker_loop
    data = fetcher.fetch(index)
  File "/home/yu-jw19/.local/lib/python3.9/site-packages/torch/utils/data/_utils/fetch.py", line 44, in fetch
    data = [self.dataset[idx] for idx in possibly_batched_index]
  File "/home/yu-jw19/.local/lib/python3.9/site-packages/torch/utils/data/_utils/fetch.py", line 44, in <listcomp>
    data = [self.dataset[idx] for idx in possibly_batched_index]
  File "/home/yu-jw19/venom/project2/dataset.py", line 46, in __getitem__
    im = self.transform(im)
  File "/home/yu-jw19/.local/lib/python3.9/site-packages/torchvision/transforms/transforms.py", line 60, in __call__
    img = t(img)
  File "/home/yu-jw19/venom/project2/aug_lib.py", line 723, in __call__
    img = op.pil_transformer(1., self.m)(img)
  File "/home/yu-jw19/venom/project2/aug_lib.py", line 92, in __call__
    return self.f(pil_img)
  File "/home/yu-jw19/venom/project2/aug_lib.py", line 108, in return_function
    im = self.xform(im, level)
  File "/home/yu-jw19/venom/project2/aug_lib.py", line 326, in _brightness_impl
    return ImageEnhance.Brightness(img).enhance(1+v)
  File "/home/yu-jw19/.local/lib/python3.9/site-packages/PIL/ImageEnhance.py", line 36, in enhance
    return Image.blend(self.degenerate, self.image, factor)
  File "/home/yu-jw19/.local/lib/python3.9/site-packages/PIL/Image.py", line 3011, in blend
    return im1._new(core.blend(im1.im, im2.im, alpha))
ValueError: image has wrong mode